<?xml version="1.0" ?>
<sdf version="1.8">
  <model name="zephyr_delta_wing">
    <pose>0 0 0.02577 0 0 0</pose>
    <static>false</static>

    <link name="wing">
      <inertial>
        <pose>0 -0.12 0 0 0 0</pose>
        <mass>1.5</mass>
        <inertia>
          <ixx>0.083137104</ixx>
          <ixy>0</ixy>
          <iyy>0.387382402</iyy>
          <ixz>0</ixz>
          <iyz>0</iyz>
          <izz>0.469845106</izz>
        </inertia>
      </inertial>
      <visual name="visual">
        <geometry>
          <mesh>
            <uri>model://zephyr_delta_wing/meshes/wing.dae</uri>
            <submesh>
              <name>Wing</name>
              <center>true</center>
            </submesh>
          </mesh>
        </geometry>
      </visual>
      <collision name="body_collision">
        <geometry>
          <mesh>
            <uri>model://zephyr_delta_wing/meshes/wing.dae</uri>
            <submesh>
              <name>Wing</name>
              <center>true</center>
            </submesh>
          </mesh>
        </geometry>
      </collision>
      <collision name="right_rudder_collision">
        <pose>-0.76435 0.33918 0.002 -0.03 0 0</pose>
        <geometry>
          <box>
            <size>.005 0.12993 .12688</size>
          </box>
        </geometry>
      </collision>
      <collision name="left_rudder_collision">
        <pose>0.76435 0.33918 0.002 -0.03 0 0</pose>
        <geometry>
          <box>
            <size>.005 0.12993 .12688</size>
          </box>
        </geometry>
      </collision>

      <!-- SENSORS -->
      <!-- GPS -->
      <sensor name="gps_sensor" type="navsat">
        <pose>0 0 0 0 0 0</pose>
        <update_rate>10.0</update_rate>
        <always_on>true</always_on>
        <topic>navsat</topic>
        <navsat/>
      </sensor>
    </link>

    <!-- Barometer -->
    <sensor name="barometer_sensor" type="air_pressure">
      <always_on>true</always_on>
      <update_rate>20</update_rate>

      <noise type="gaussian">
        <mean>0.0</mean>
        <stddev>5.0</stddev> <!-- Pa -->
      </noise>

      <plugin filename="gz-sim-air-pressure-system"
              name="gz::sim::systems::AirPressure">
        <topic>/air_pressure</topic>
      </plugin>
    </sensor>

    <!-- IMU -->
    <sensor name="imu_sensor" type="imu">
      <always_on>true</always_on>
      <update_rate>100</update_rate>

      <noise type="gaussian">
        <mean>0.0</mean>
        <stddev>0.02</stddev> <!-- accelerometer noise (m/s^2) -->
      </noise>

      <angular_velocity>
        <noise type="gaussian">
          <mean>0.0</mean>
          <stddev>0.001</stddev> <!-- gyro noise (rad/s) -->
        </noise>
      </angular_velocity>

      <linear_acceleration>
        <noise type="gaussian">
          <mean>0.0</mean>
          <stddev>0.02</stddev> <!-- accel noise (m/s^2) -->
        </noise>
      </linear_acceleration>

      <plugin filename="gz-sim-imu-system"
              name="gz::sim::systems::Imu">
        <topic>/imu</topic>
      </plugin>
    </sensor>

    <!-- Magnetometer -->
    <sensor name="magnetometer_sensor" type="magnetometer">
      <always_on>true</always_on>
      <update_rate>50</update_rate>

      <noise type="gaussian">
        <mean>0.0</mean>
        <stddev>0.01</stddev> <!-- Tesla -->
      </noise>

      <plugin filename="gz-sim-magnetometer-system"
              name="gz::sim::systems::Magnetometer">
        <topic>/magnetometer</topic>
      </plugin>
    </sensor>

    <link name="propeller">
      <!--<pose>0 0.1174 -0.007 0 1.5707 0</pose>-->
      <pose>0 0.07 0.008 0 0 0</pose>
      <inertial>
        <mass>.05</mass>
        <inertia>
          <ixx>0.000367571</ixx>
          <ixy>0</ixy>
          <iyy>0.00036985</iyy>
          <ixz>0</ixz>
          <iyz>0</iyz>
          <izz>0.000003187</izz>
        </inertia>
      </inertial>
      <visual name="visual">
        <geometry>
          <mesh>
            <uri>model://zephyr_delta_wing/meshes/wing.dae</uri>
            <submesh>
              <name>Propeller</name>
              <center>true</center>
            </submesh>
          </mesh>
        </geometry>
      </visual>
      <collision name="blade1">
        <pose>0 0 0.074205 0 0  0.3</pose>
        <geometry>
          <box>
            <size>0.02561 0.00541 0.14841</size>
          </box>
        </geometry>
      </collision>
      <collision name="blade2">
        <pose>0 0 -0.074205 0 0  -0.3</pose>
        <geometry>
          <box>
            <size>0.02561 0.00541 0.14841</size>
          </box>
        </geometry>
      </collision>
    </link>

    <link name="flap_left">
      <pose>0.4530 .239 0.007 0 0 0</pose>
      <inertial>
        <pose>0 0 0 0 0 0.32445671</pose>
        <mass>.1</mass>
        <inertia>
          <ixx>0.000102319</ixx>
          <ixy>0</ixy>
          <iyy>0.00334417</iyy>
          <ixz>0</ixz>
          <iyz>0</iyz>
          <izz>0.003446072</izz>
        </inertia>
      </inertial>
      <visual name="visual">
        <geometry>
          <mesh>
            <uri>model://zephyr_delta_wing/meshes/wing.dae</uri>
            <submesh>
              <name>Flap_Left</name>
              <center>true</center>
            </submesh>
          </mesh>
        </geometry>
      </visual>
      <collision name="collision">
        <pose>-0.01 0.01 0 0 0 0.32445671</pose>
        <geometry>
          <box>
            <size>0.633463031 0.110694312 0.005</size>
          </box>
        </geometry>
      </collision>
    </link>

    <link name="flap_right">
      <pose>-0.4530 .239 0.007 0 0 0</pose>
      <inertial>
        <pose>0 0 0 0 0 -0.32445671</pose>
        <mass>.1</mass>
        <inertia>
          <ixx>0.000102319</ixx>
          <ixy>0</ixy>
          <iyy>0.00334417</iyy>
          <ixz>0</ixz>
          <iyz>0</iyz>
          <izz>0.003446072</izz>
        </inertia>
      </inertial>
      <visual name="visual">
        <geometry>
          <mesh>
            <uri>model://zephyr_delta_wing/meshes/wing.dae</uri>
            <submesh>
              <name>Flap_Right</name>
              <center>true</center>
            </submesh>
          </mesh>
        </geometry>
      </visual>
      <collision name="collision">
        <pose>0.01 0.01 0 0 0 -0.32445671</pose>
        <geometry>
          <box>
            <size>0.633463031 0.110694312 0.005</size>
          </box>
        </geometry>
      </collision>
    </link>

    <joint name="propeller_joint" type="revolute">
      <parent>wing</parent>
      <child>propeller</child>
      <axis>
        <xyz>0 -1 0</xyz>
        <dynamics>
          <damping>0.002</damping>
        </dynamics>
        <limit>
          <effort>50</effort>
          <velocity>500.0</velocity>
        </limit>
      </axis>
      <physics>
        <ode>
          <implicit_spring_damper>1</implicit_spring_damper>
        </ode>
      </physics>
    </joint>

    <joint name="flap_left_joint" type="revolute">
      <parent>wing</parent>
      <child>flap_left</child>
      <pose>0 -0.04 0 0 0 0</pose>
      <axis>
        <xyz>1 0.330321014 0</xyz>
        <limit>
          <lower>-0.524</lower>
          <upper>0.524</upper>
        </limit>
        <dynamics>
          <damping>0.1</damping>
        </dynamics>
      </axis>
      <physics>
        <ode>
          <implicit_spring_damper>1</implicit_spring_damper>
        </ode>
      </physics>
    </joint>

    <joint name="flap_right_joint" type="revolute">
      <parent>wing</parent>
      <child>flap_right</child>
      <pose>0 -0.04 0 0 0 0</pose>
      <axis>
        <xyz>1 -0.330321014 0</xyz>
        <limit>
          <lower>-0.524</lower>
          <upper>0.524</upper>
        </limit>
        <dynamics>
          <damping>0.1</damping>
        </dynamics>
      </axis>
      <physics>
        <ode>
          <implicit_spring_damper>1</implicit_spring_damper>
        </ode>
      </physics>
    </joint>

    <!-- LiftDrag plugins converted to Harmonic systems -->
    <plugin name="gz::sim::systems::LiftDrag" filename="libgz-sim8-lift-drag-system">
      <a0>0.13</a0>
      <cla>3.7</cla>
      <cda>0.06417112299</cda>
      <cma>-1.8</cma>
      <alpha_stall>0.3391428111</alpha_stall>
      <cla_stall>-3.85</cla_stall>
      <cda_stall>-0.9233984055</cda_stall>
      <cma_stall>0</cma_stall>
      <cp>0 -0.1 0</cp>
      <area>0.50</area>
      <air_density>1.2041</air_density>
      <forward>0 -1 0</forward>
      <upward>0 0 1</upward>
      <link_name>wing</link_name>
    </plugin>

    <!-- Left wing -->
    <plugin name="gz::sim::systems::LiftDrag" filename="libgz-sim8-lift-drag-system">
      <a0>0.15</a0>
      <cla>6.8</cla>
      <cda>0.06417112299</cda>
      <cma>-1.8</cma>
      <alpha_stall>0.6391428111</alpha_stall>
      <cla_stall>-3.85</cla_stall>
      <cda_stall>-0.9233984055</cda_stall>
      <cma_stall>0</cma_stall>
      <cp>0.7 0.20 0</cp>
      <area>0.10</area>
      <air_density>1.2041</air_density>
      <forward>0 -1 0</forward>
      <upward>0 0 1</upward>
      <link_name>wing</link_name>
      <control_joint_name>flap_left_joint</control_joint_name>
      <control_joint_rad_to_cl>-5.0</control_joint_rad_to_cl>
    </plugin>

    <!-- Right wing -->
    <plugin name="gz::sim::systems::LiftDrag" filename="libgz-sim8-lift-drag-system">
      <a0>0.15</a0>
      <cla>6.8</cla>
      <cda>0.06417112299</cda>
      <cma>-1.8</cma>
      <alpha_stall>0.6391428111</alpha_stall>
      <cla_stall>-3.85</cla_stall>
      <cda_stall>-0.9233984055</cda_stall>
      <cma_stall>0</cma_stall>
      <cp>-0.7 0.20 0</cp>
      <area>0.10</area>
      <air_density>1.2041</air_density>
      <forward>0 -1 0</forward>
      <upward>0 0 1</upward>
      <link_name>wing</link_name>
      <control_joint_name>flap_right_joint</control_joint_name>
      <control_joint_rad_to_cl>-5.0</control_joint_rad_to_cl>
    </plugin>

    <!-- Left rudder -->
    <plugin name="gz::sim::systems::LiftDrag" filename="libgz-sim8-lift-drag-system">
      <a0>0.0</a0>
      <cla>4.752798721</cla>
      <cda>0.6417112299</cda>
      <cma>-1.8</cma>
      <alpha_stall>0.3391428111</alpha_stall>
      <cla_stall>-3.85</cla_stall>
      <cda_stall>-0.9233984055</cda_stall>
      <cma_stall>0</cma_stall>
      <cp>-0.76 0.30 0.025</cp>
      <area>0.12</area>
      <air_density>1.2041</air_density>
      <forward>0 -1 0</forward>
      <upward>1 0 0</upward>
      <link_name>wing</link_name>
    </plugin>

    <!-- Right rudder -->
    <plugin name="gz::sim::systems::LiftDrag" filename="libgz-sim8-lift-drag-system">
      <a0>0.0</a0>
      <cla>4.752798721</cla>
      <cda>0.6417112299</cda>
      <cma>-1.8</cma>
      <alpha_stall>0.3391428111</alpha_stall>
      <cla_stall>-3.85</cla_stall>
      <cda_stall>-0.9233984055</cda_stall>
      <cma_stall>0</cma_stall>
      <cp>0.76 0.30 0.025</cp>
      <area>0.12</area>
      <air_density>1.2041</air_density>
      <forward>0 -1 0</forward>
      <upward>1 0 0</upward>
      <link_name>wing</link_name>
    </plugin>

    <!-- Left propeller blade -->
    <plugin name="gz::sim::systems::LiftDrag" filename="libgz-sim8-lift-drag-system">
      <a0>0.30</a0>
      <alpha_stall>1.4</alpha_stall>
      <cla>10.00</cla> <!-- was 4.25 -->
      <cda>0.10</cda>
      <cma>0.00</cma>
      <cla_stall>-0.025</cla_stall>
      <cda_stall>0.0</cda_stall>
      <cma_stall>0.0</cma_stall>
      <area>0.1</area> <!-- was 0.02 -->
      <air_density>1.2041</air_density>
      <cp>0 0 0.074205</cp>
      <forward>1 0 0</forward>
      <upward>0 0 1</upward>
      <link_name>propeller</link_name>
    </plugin>

    <!-- Right propeller blade -->
    <plugin name="gz::sim::systems::LiftDrag" filename="libgz-sim8-lift-drag-system">
      <a0>0.30</a0>
      <alpha_stall>1.4</alpha_stall>
      <cla>10.00</cla> <!-- was 4.25 -->
      <cda>0.10</cda>
      <cma>0.00</cma>
      <cla_stall>-0.025</cla_stall>
      <cda_stall>0.0</cda_stall>
      <cma_stall>0.0</cma_stall>
      <area>0.1</area> <!-- was 0.02 -->
      <air_density>1.2041</air_density>
      <cp>0 0 -0.074205</cp>
      <forward>-1 0 0</forward>
      <upward>0 0 -1</upward>
      <link_name>propeller</link_name>
    </plugin>

    <!-- Joint controller for propeller (Harmonic system) -->
    <plugin name="gz::sim::systems::JointController"
            filename="libgz-sim8-joint-controller-system">
      <joint_name>propeller_joint</joint_name>
      <velocity_topic>/model/zephyr_delta_wing/joint/propeller_joint/cmd_vel</velocity_topic>
    </plugin>

  </model>
</sdf>
