<?xml version="1.0"?>
<robot xmlns:xacro="http://www.ros.org/wiki/xacro"
       name="zephyr_delta_wing">

  <!-- 1) ARGUMENTER -->
  <xacro:arg name="prefix"      default=""/>
  <xacro:arg name="namespace"   default="zephyr"/>
  <xacro:arg name="pkg"         default="package://drone_sim"/>

  <!-- 2) PROPERTIES -->
  <xacro:property name="meshes" value="$(arg pkg)/models/zephyr_delta_wing/meshes"/>

  <!-- 3) BASE LINK -->
  <link name="$(arg prefix)base_link">
    <inertial>
      <origin xyz="0 -0.12 0" rpy="0 0 0"/>
      <mass value="1.5"/>
      <inertia
        ixx="0.083137104" ixy="0" ixz="0"
        iyy="0.387382402" iyz="0"
        izz="0.469845106"/>
    </inertial>

    <visual>
      <origin xyz="0 0 0" rpy="0 0 0"/>
      <geometry>
        <mesh filename="${meshes}/wing.dae"/>
      </geometry>
    </visual>

    <collision>
      <origin xyz="0 0 0" rpy="0 0 0"/>
      <geometry>
        <mesh filename="${meshes}/wing.dae"/>
      </geometry>
    </collision>

    <collision name="right_rudder_collision">
      <origin xyz="-0.76435 0.33918 0.002" rpy="-0.03 0 0"/>
      <geometry>
        <box size="0.005 0.12993 0.12688"/>
      </geometry>
    </collision>

    <collision name="left_rudder_collision">
      <origin xyz="0.76435 0.33918 0.002" rpy="-0.03 0 0"/>
      <geometry>
        <box size="0.005 0.12993 0.12688"/>
      </geometry>
    </collision>
  </link>

  <!-- 4) PROPELLER LINK -->
  <link name="$(arg prefix)propeller">
    <inertial>
      <origin xyz="0 0 0" rpy="0 0 0"/>
      <mass value="0.05"/>
      <inertia
        ixx="0.000367571" ixy="0" ixz="0"
        iyy="0.00036985"  iyz="0"
        izz="0.000003187"/>
    </inertial>

    <visual>
      <origin xyz="0 0 0" rpy="0 0 0"/>
      <geometry>
        <cylinder length="0.01" radius="0.05"/>
      </geometry>
    </visual>

    <collision name="blade1">
      <origin xyz="0 0 0.074205" rpy="0 0 0.3"/>
      <geometry>
        <box size="0.02561 0.00541 0.14841"/>
      </geometry>
    </collision>

    <collision name="blade2">
      <origin xyz="0 0 -0.074205" rpy="0 0 -0.3"/>
      <geometry>
        <box size="0.02561 0.00541 0.14841"/>
      </geometry>
    </collision>
  </link>

  <!-- 5) FLAPS -->
  <link name="$(arg prefix)flap_left">
    <inertial>
      <origin xyz="0 0 0" rpy="0 0 0.32445671"/>
      <mass value="0.1"/>
      <inertia
        ixx="0.000102319" ixy="0" ixz="0"
        iyy="0.00334417"  iyz="0"
        izz="0.003446072"/>
    </inertial>

    <visual>
      <origin xyz="0 0 0" rpy="0 0 0"/>
      <geometry>
        <box size="0.6 0.1 0.01"/>
      </geometry>
    </visual>

    <collision>
      <origin xyz="-0.01 0.01 0" rpy="0 0 0.32445671"/>
      <geometry>
        <box size="0.633463031 0.110694312 0.005"/>
      </geometry>
    </collision>
  </link>

  <link name="$(arg prefix)flap_right">
    <inertial>
      <origin xyz="0 0 0" rpy="0 0 -0.32445671"/>
      <mass value="0.1"/>
      <inertia
        ixx="0.000102319" ixy="0" ixz="0"
        iyy="0.00334417"  iyz="0"
        izz="0.003446072"/>
    </inertial>

    <visual>
      <origin xyz="0 0 0" rpy="0 0 0"/>
      <geometry><box size="0.6 0.1 0.01"/></geometry>
    </visual>

    <collision>
      <origin xyz="0.01 0.01 0" rpy="0 0 -0.32445671"/>
      <geometry><box size="0.633463031 0.110694312 0.005"/></geometry>
    </collision>
  </link>

  <!-- 6) JOINTS -->
  <joint name="propeller_joint" type="continuous">
    <parent link="$(arg prefix)base_link"/>
    <child  link="$(arg prefix)propeller"/>
    <origin xyz="0 0.07 0.008" rpy="0 1.5707 0"/>
    <axis xyz="0 -1 0"/>
    <limit effort="1.0" velocity="100.0"/>
  </joint>

  <joint name="flap_left_joint" type="revolute">
    <parent link="$(arg prefix)base_link"/>
    <child  link="$(arg prefix)flap_left"/>
    <origin xyz="0.4530 0.239 0.007" rpy="0 0 0"/>
    <axis xyz="1 0.330321014 0"/>
    <limit lower="-0.524" upper="0.524" effort="1.0" velocity="1.0"/>
  </joint>

  <joint name="flap_right_joint" type="revolute">
    <parent link="$(arg prefix)base_link"/>
    <child  link="$(arg prefix)flap_right"/>
    <origin xyz="-0.4530 0.239 0.007" rpy="0 0 0"/>
    <axis xyz="1 -0.330321014 0"/>
    <limit lower="-0.524" upper="0.524" effort="1.0" velocity="1.0"/>
  </joint>

  <!-- 7) CAMERA LINKS (TF ONLY) -->
  <link name="$(arg prefix)camera_left_link">
    <visual>
      <origin xyz="0 0 0" rpy="0 0 0"/>
      <geometry><box size="0.03 0.03 0.03"/></geometry>
    </visual>
  </link>

  <joint name="$(arg prefix)camera_left_joint" type="fixed">
    <parent link="$(arg prefix)base_link"/>
    <child link="$(arg prefix)camera_left_link"/>
    <origin xyz="0.0 0.05 0.1" rpy="0 0 0"/>
  </joint>

  <link name="$(arg prefix)camera_right_link">
    <visual>
      <origin xyz="0 0 0" rpy="0 0 0"/>
      <geometry><box size="0.03 0.03 0.03"/></geometry>
    </visual>
  </link>

  <joint name="$(arg prefix)camera_right_joint" type="fixed">
    <parent link="$(arg prefix)base_link"/>
    <child link="$(arg prefix)camera_right_link"/>
    <origin xyz="0.0 -0.05 0.1" rpy="0 0 0"/>
  </joint>

</robot>
